<?xml version="1.0"?>

<robot name="drawer">
  
  <link name="drawer_bottom_1">
    <contact>
      <restitution value="1.0e-8" />
      <!-- <lateral_friction value="1.0"/> -->
      <!-- <rolling_friction value="1.0e+8"/> 
      <spinning_friction value="1.0e+8"/>  -->
      <contact_cfm value="0.00001"/>
      <contact_erp value="0.2"/>
    </contact>
    
    <inertial>
      <origin xyz="0 0 0" />
      <mass value="0.1" />
      <inertia  ixx="1" ixy="0.0"  ixz="0.0"  iyy="1"  iyz="0.0"  izz="1" />
    </inertial>

    <visual>
      <origin xyz="0 0 0"/>
      <geometry>
        <box size="0.145 0.184 0.01"/>
      </geometry>
      <material name="LightBule">
        <color rgba="1. 1. 0. 1.0"/>
      </material>zz
    </visual>

    <collision>
      <origin xyz="0 0 0"/>
      <geometry>
        <box size="0.145 0.184 0.01"/>
      </geometry>
    </collision>

  </link>


  <joint name="0" type="fixed">
    <parent link="drawer_bottom_1"/>
    <child link="drawer_bottom_1_right"/>
    <origin rpy="0 0 0" xyz="0.0725 0.0 0.077" />
  </joint>



  <link name="drawer_bottom_1_right">
    <contact>
      <restitution value="1.0e-8" />
      <!-- <lateral_friction value="1.0"/> -->
      <!-- <rolling_friction value="1.0e+8"/> 
      <spinning_friction value="1.0e+8"/>  -->
      <contact_cfm value="0.00001"/>
      <contact_erp value="0.2"/>
    </contact>
    
    <inertial>
      <origin xyz="0 0 0" />
      <mass value="0.1" />
      <inertia  ixx="1" ixy="0.0"  ixz="0.0"  iyy="1"  iyz="0.0"  izz="1" />
    </inertial>

    <visual>
      <origin xyz="0 0 0"/>
      <geometry>
        <box size="0.01 0.184 0.164"/>
      </geometry>
      <material name="LightBule">
        <color rgba="1. 1. 0. 1.0"/>
      </material>zz
    </visual>

    <collision>
      <origin xyz="0 0 0"/>
      <geometry>
        <box size="0.01 0.184 0.164"/>
      </geometry>
    </collision>

  </link>


  <joint name="1" type="fixed">
    <parent link="drawer_bottom_1"/>
    <child link="drawer_bottom_1_left"/>
    <origin rpy="0 0 0" xyz="-0.0725 0.0 0.077" />
  </joint>


  <link name="drawer_bottom_1_left">
    <contact>
      <restitution value="1.0e-8" />
      <!-- <lateral_friction value="1.0"/> -->
      <!-- <rolling_friction value="1.0e+8"/> 
      <spinning_friction value="1.0e+8"/>  -->
      <contact_cfm value="0.00001"/>
      <contact_erp value="0.2"/>
    </contact>
    
    <inertial>
      <origin xyz="0 0 0" />
      <mass value="0.1" />
      <inertia  ixx="1" ixy="0.0"  ixz="0.0"  iyy="1"  iyz="0.0"  izz="1" />
    </inertial>

    <visual>
      <origin xyz="0 0 0"/>
      <geometry>
        <box size="0.01 0.184 0.164"/>
      </geometry>
      <material name="LightBule">
        <color rgba="1. 1. 0. 1.0"/>
      </material>zz
    </visual>

    <collision>
      <origin xyz="0 0 0"/>
      <geometry>
        <box size="0.01 0.184 0.164"/>
      </geometry>
    </collision>

  </link>


  <joint name="2" type="fixed">
    <parent link="drawer_bottom_1"/>
    <child link="drawer_bottom_1_top"/>
    <origin rpy="0 0 0" xyz="0 0.0 0.154" />
  </joint>


  <link name="drawer_bottom_1_top">
    <contact>
      <restitution value="1.0e-8" />
      <!-- <lateral_friction value="1.0"/> -->
      <!-- <rolling_friction value="1.0e+8"/> 
      <spinning_friction value="1.0e+8"/>  -->
      <contact_cfm value="0.00001"/>
      <contact_erp value="0.2"/>
    </contact>
    
    <inertial>
      <origin xyz="0 0 0" />
      <mass value="0.1" />
      <inertia  ixx="1" ixy="0.0"  ixz="0.0"  iyy="1"  iyz="0.0"  izz="1" />
    </inertial>

    <visual>
      <origin xyz="0 0 0"/>
      <geometry>
        <box size="0.145 0.184 0.01"/>
      </geometry>
      <material name="LightBule">
        <color rgba="1. 1. 0. 1.0"/>
      </material>zz
    </visual>

    <collision>
      <origin xyz="0 0 0"/>
      <geometry>
        <box size="0.145 0.184 0.01"/>
      </geometry>
    </collision>

  </link>

  <joint name="3" type="fixed">
    <parent link="drawer_bottom_1"/>
    <child link="drawer_bottom_1_mid"/>
    <origin rpy="0 0 0" xyz="0 0.0 0.077" />
  </joint>


  <link name="drawer_bottom_1_mid">
    <contact>
      <restitution value="1.0e-8" />
      <!-- <lateral_friction value="1.0"/> -->
      <!-- <rolling_friction value="1.0e+8"/> 
      <spinning_friction value="1.0e+8"/>  -->
      <contact_cfm value="0.00001"/>
      <contact_erp value="0.2"/>
    </contact>
    
    <inertial>
      <origin xyz="0 0 0" />
      <mass value="0.1" />
      <inertia  ixx="1" ixy="0.0"  ixz="0.0"  iyy="1"  iyz="0.0"  izz="1" />
    </inertial>

    <visual>
      <origin xyz="0 0 0"/>
      <geometry>
        <box size="0.145 0.184 0.01"/>
      </geometry>
      <material name="LightBule">
        <color rgba="1. 1. 0. 1.0"/>
      </material>zz
    </visual>

    <collision>
      <origin xyz="0 0 0"/>
      <geometry>
        <box size="0.145 0.184 0.01"/>
      </geometry>
    </collision>

  </link>

  <joint name="4" type="prismatic">
    <parent link="drawer_bottom_1_mid"/>
    <child link="drawer_bottom_1_mid_flat"/>
    <origin rpy="0 0 0" xyz="0 -0.0 0.008" />
    <axis xyz ="0 -1 0" />
    <limit lower="0" upper="0.12" effort="0.0" velocity="3.15"/>
  </joint>


  <link name="drawer_bottom_1_mid_flat">
    <contact>
      <restitution value="1.0e-8" />
      <!-- <lateral_friction value="1.0"/> -->
      <!-- <rolling_friction value="1.0e+8"/> 
      <spinning_friction value="1.0e+8"/>  -->
      <contact_cfm value="0.00001"/>
      <contact_erp value="0.2"/>
    </contact>
    
    <inertial>
      <origin xyz="0 0 0" />
      <mass value="0.1" />
      <inertia  ixx="1" ixy="0.0"  ixz="0.0"  iyy="1"  iyz="0.0"  izz="1" />
    </inertial>

    <visual>
      <origin xyz="0 0 0"/>
      <geometry>
        <box size="0.127 0.177 0.003"/>
      </geometry>
      <material name="LightBule">
        <color rgba="1. 1. 0. 1.0"/>
      </material>zz
    </visual>

    <collision>
      <origin xyz="0 0 0"/>
      <geometry>
        <box size="0.127 0.177 0.003"/>
      </geometry>
    </collision>

  </link>

  <joint name="5" type="fixed">
    <parent link="drawer_bottom_1_mid_flat"/>
    <child link="drawer_bottom_1_mid_flat_right"/>
    <origin rpy="0 0 0" xyz="0.065 0.0 0.031" />
  </joint>


  <link name="drawer_bottom_1_mid_flat_right">
    <contact>
      <restitution value="1.0e-8" />
      <!-- <lateral_friction value="1.0"/> -->
      <!-- <rolling_friction value="1.0e+8"/> 
      <spinning_friction value="1.0e+8"/>  -->
      <contact_cfm value="0.00001"/>
      <contact_erp value="0.2"/>
    </contact>
    
    <inertial>
      <origin xyz="0 0 0" />
      <mass value="0.1" />
      <inertia  ixx="1" ixy="0.0"  ixz="0.0"  iyy="1"  iyz="0.0"  izz="1" />
    </inertial>

    <visual>
      <origin xyz="0 0 0"/>
      <geometry>
        <box size="0.003 0.177 0.065"/>
      </geometry>
      <material name="LightBule">
        <color rgba="1. 1. 0. 1.0"/>
      </material>zz
    </visual>

    <collision>
      <origin xyz="0 0 0"/>
      <geometry>
        <box size="0.003 0.177 0.065"/>
      </geometry>
    </collision>

  </link>

  <joint name="6" type="fixed">
    <parent link="drawer_bottom_1_mid_flat"/>
    <child link="drawer_bottom_1_mid_flat_left"/>
    <origin rpy="0 0 0" xyz="-0.065 0.0 0.031" />
  </joint>

  <link name="drawer_bottom_1_mid_flat_left">
    <contact>
      <restitution value="1.0e-8" />
      <!-- <lateral_friction value="1.0"/> -->
      <!-- <rolling_friction value="1.0e+8"/> 
      <spinning_friction value="1.0e+8"/>  -->
      <contact_cfm value="0.00001"/>
      <contact_erp value="0.2"/>
    </contact>
    
    <inertial>
      <origin xyz="0 0 0" />
      <mass value="0.1" />
      <inertia  ixx="1" ixy="0.0"  ixz="0.0"  iyy="1"  iyz="0.0"  izz="1" />
    </inertial>

    <visual>
      <origin xyz="0 0 0"/>
      <geometry>
        <box size="0.003 0.177 0.065"/>
      </geometry>
      <material name="LightBule">
        <color rgba="1. 1. 0. 1.0"/>
      </material>zz
    </visual>

    <collision>
      <origin xyz="0 0 0"/>
      <geometry>
        <box size="0.003 0.177 0.065"/>
      </geometry>
    </collision>

  </link>

  <joint name="7" type="fixed">
    <parent link="drawer_bottom_1_mid_flat"/>
    <child link="drawer_bottom_1_mid_flat_front"/>
    <origin rpy="0 0 0" xyz="0 -0.087 0.031" />
  </joint>

  <link name="drawer_bottom_1_mid_flat_front">
    <contact>
      <restitution value="1.0e-8" />
      <!-- <lateral_friction value="1.0"/> -->
      <!-- <rolling_friction value="1.0e+8"/> 
      <spinning_friction value="1.0e+8"/>  -->
      <contact_cfm value="0.00001"/>
      <contact_erp value="0.2"/>
    </contact>
    
    <inertial>
      <origin xyz="0 0 0" />
      <mass value="0.1" />
      <inertia  ixx="1" ixy="0.0"  ixz="0.0"  iyy="1"  iyz="0.0"  izz="1" />
    </inertial>

    <visual>
      <origin xyz="0 0 0"/>
      <geometry>
        <box size="0.127 0.003 0.065"/>
      </geometry>
      <material name="LightBule">
        <color rgba="1. 1. 0. 1.0"/>
      </material>zz
    </visual>

    <collision>
      <origin xyz="0 0 0"/>
      <geometry>
        <box size="0.127 0.003 0.065"/>
      </geometry>
    </collision>

  </link>


  <joint name="8" type="prismatic">
    <parent link="drawer_bottom_1"/>
    <child link="drawer_bottom_1_bottom_flat"/>
    <origin rpy="0 0 0" xyz="0 0.0 0.008" />
    <axis xyz ="0 -1 0" />
    <limit lower="0" upper="0.12" effort="0.0" velocity="3.15"/>
  </joint>


  <link name="drawer_bottom_1_bottom_flat">
    <contact>
      <restitution value="1.0e-8" />
      <!-- <lateral_friction value="1.0"/> -->
      <!-- <rolling_friction value="1.0e+8"/> 
      <spinning_friction value="1.0e+8"/>  -->
      <contact_cfm value="0.00001"/>
      <contact_erp value="0.2"/>
    </contact>
    
    <inertial>
      <origin xyz="0 0 0" />
      <mass value="0.1" />
      <inertia  ixx="1" ixy="0.0"  ixz="0.0"  iyy="1"  iyz="0.0"  izz="1" />
    </inertial>

    <visual>
      <origin xyz="0 0 0"/>
      <geometry>
        <box size="0.127 0.177 0.003"/>
      </geometry>
      <material name="LightBule">
        <color rgba="1. 1. 0. 1.0"/>
      </material>zz
    </visual>

    <collision>
      <origin xyz="0 0 0"/>
      <geometry>
        <box size="0.127 0.177 0.003"/>
      </geometry>
    </collision>

  </link>

  <joint name="9" type="fixed">
    <parent link="drawer_bottom_1_bottom_flat"/>
    <child link="drawer_bottom_1_bottom_flat_right"/>
    <origin rpy="0 0 0" xyz="0.065 0.0 0.031" />
  </joint>


  <link name="drawer_bottom_1_bottom_flat_right">
    <contact>
      <restitution value="1.0e-8" />
      <!-- <lateral_friction value="1.0"/> -->
      <!-- <rolling_friction value="1.0e+8"/> 
      <spinning_friction value="1.0e+8"/>  -->
      <contact_cfm value="0.00001"/>
      <contact_erp value="0.2"/>
    </contact>
    
    <inertial>
      <origin xyz="0 0 0" />
      <mass value="0.1" />
      <inertia  ixx="1" ixy="0.0"  ixz="0.0"  iyy="1"  iyz="0.0"  izz="1" />
    </inertial>

    <visual>
      <origin xyz="0 0 0"/>
      <geometry>
        <box size="0.003 0.177 0.065"/>
      </geometry>
      <material name="LightBule">
        <color rgba="1. 1. 0. 1.0"/>
      </material>zz
    </visual>

    <collision>
      <origin xyz="0 0 0"/>
      <geometry>
        <box size="0.003 0.177 0.065"/>
      </geometry>
    </collision>

  </link>

  <joint name="10" type="fixed">
    <parent link="drawer_bottom_1_bottom_flat"/>
    <child link="drawer_bottom_1_bottom_flat_left"/>
    <origin rpy="0 0 0" xyz="-0.065 0.0 0.031" />
  </joint>

  <link name="drawer_bottom_1_bottom_flat_left">
    <contact>
      <restitution value="1.0e-8" />
      <!-- <lateral_friction value="1.0"/> -->
      <!-- <rolling_friction value="1.0e+8"/> 
      <spinning_friction value="1.0e+8"/>  -->
      <contact_cfm value="0.00001"/>
      <contact_erp value="0.2"/>
    </contact>
    
    <inertial>
      <origin xyz="0 0 0" />
      <mass value="0.1" />
      <inertia  ixx="1" ixy="0.0"  ixz="0.0"  iyy="1"  iyz="0.0"  izz="1" />
    </inertial>

    <visual>
      <origin xyz="0 0 0"/>
      <geometry>
        <box size="0.003 0.177 0.065"/>
      </geometry>
      <material name="LightBule">
        <color rgba="1. 1. 0. 1.0"/>
      </material>zz
    </visual>

    <collision>
      <origin xyz="0 0 0"/>
      <geometry>
        <box size="0.003 0.177 0.065"/>
      </geometry>
    </collision>

  </link>

  <joint name="11" type="fixed">
    <parent link="drawer_bottom_1_bottom_flat"/>
    <child link="drawer_bottom_1_bottom_flat_front"/>
    <origin rpy="0 0 0" xyz="0 -0.087 0.031" />
  </joint>

  <link name="drawer_bottom_1_bottom_flat_front">
    <contact>
      <restitution value="1.0e-8" />
      <!-- <lateral_friction value="1.0"/> -->
      <!-- <rolling_friction value="1.0e+8"/> 
      <spinning_friction value="1.0e+8"/>  -->
      <contact_cfm value="0.00001"/>
      <contact_erp value="0.2"/>
    </contact>
    
    <inertial>
      <origin xyz="0 0 0" />
      <mass value="0.1" />
      <inertia  ixx="1" ixy="0.0"  ixz="0.0"  iyy="1"  iyz="0.0"  izz="1" />
    </inertial>

    <visual>
      <origin xyz="0 0 0"/>
      <geometry>
        <box size="0.127 0.003 0.065"/>
      </geometry>
      <material name="LightBule">
        <color rgba="1. 1. 0. 1.0"/>
      </material>zz
    </visual>

    <collision>
      <origin xyz="0 0 0"/>
      <geometry>
        <box size="0.127 0.003 0.065"/>
      </geometry>
    </collision>

  </link>



</robot>
